Workbook

Sheet Permutinha2.0
A1: Poder de Barganha | B1: Trocas | D1: Full Barter Stock
A2: 81593 | B2: =DIVIDE(A2,A24) -> 9.3741958 | F2: Tier 1 | I2: [Level 2] Balanced Stone Pagoda | J2: Tier 2 | N2: Tier 3 | R2: Tier 4 | V2: Tier 5 | Z2: Grana
A3: Nº de Trocas | B3: Trocas | E3: [Level 1] Unidentified Ancient Mural | F3: =E3 -> [Level 1] Unidentified Ancient Mural | G3: {=XLOOKUP(F3,'Exported Data'!A:A,'Exported Data'!B:B)} -> 12 | I3: ='Exported Data'!A17 -> [Level 2] Islanders' Lunchbox | J3: =I3 -> [Level 2] Islanders' Lunchbox | K3: {=XLOOKUP(J3,'Exported Data'!$A:$A,'Exported Data'!$B:$B)} -> 57 | M3: [Level 3] Blue Candle Bundle | N3: =M3 -> [Level 3] Blue Candle Bundle | O3: {=XLOOKUP(N3,'Exported Data'!$A:$A,'Exported Data'!$B:$B)} -> 34 | Q3: [Level 4] Pirate's Key | R3: =Q3 -> [Level 4] Pirate's Key | S3: {=XLOOKUP(R3,'Exported Data'!$A:$A,'Exported Data'!$B:$B)} -> 26 | U3: [Level 5] Portrait of the Ancient | V3: =U3 -> [Level 5] Portrait of the Ancient | W3: {=XLOOKUP(V3,'Exported Data'!$A:$A,'Exported Data'!$B:$B)} -> 3
A4: 9 | B4: =PRODUCT(A4,A24) -> 78336 | E4: [Level 1] Pirates' Gunpowder | F4: =E4 -> [Level 1] Pirates' Gunpowder | G4: {=XLOOKUP(F4,'Exported Data'!A:A,'Exported Data'!B:B)} -> 11 | I4: ='Exported Data'!A18 -> [Level 2] Monster Tentacle | J4: =I4 -> [Level 2] Monster Tentacle | K4: {=XLOOKUP(J4,'Exported Data'!A:A,'Exported Data'!B:B)} -> 32 | M4: [Level 3] Ancient Orders | N4: =M4 -> [Level 3] Ancient Orders | O4: {=XLOOKUP(N4,'Exported Data'!$A:$A,'Exported Data'!$B:$B)} -> 28 | Q4: [Level 4] Bronze Candlestick | R4: =Q4 -> [Level 4] Bronze Candlestick | S4: {=XLOOKUP(R4,'Exported Data'!$A:$A,'Exported Data'!$B:$B)} -> 4 | U4: [Level 5] 102 Year Old Golden Herb | V4: =U4 -> [Level 5] 102 Year Old Golden Herb | W4: {=XLOOKUP(V4,'Exported Data'!$A:$A,'Exported Data'!$B:$B)} -> 6 | AF4: TRUE | AG4: Iliya
B5: Nº | C5: 1x 2x ou 3x | D5: Peso | E5: [Level 1] Fertile Soil | F5: =E5 -> [Level 1] Fertile Soil | G5: {=XLOOKUP(F5,'Exported Data'!A:A,'Exported Data'!B:B)} -> 1 | I5: ='Exported Data'!A19 -> [Level 2] Filtered Drinking Water | J5: =I5 -> [Level 2] Filtered Drinking Water | K5: {=XLOOKUP(J5,'Exported Data'!A:A,'Exported Data'!B:B)} -> 81 | M5: [Level 3] Lopters Fishnet | N5: =M5 -> [Level 3] Lopters Fishnet | O5: {=XLOOKUP(N5,'Exported Data'!$A:$A,'Exported Data'!$B:$B)} -> 72 | Q5: [Level 4] Headless Dragon Figurine | R5: =Q5 -> [Level 4] Headless Dragon Figurine | S5: {=XLOOKUP(R5,'Exported Data'!$A:$A,'Exported Data'!$B:$B)} -> 26 | U5: [Level 5] Golden Fish Scale | V5: =U5 -> [Level 5] Golden Fish Scale | W5: {=XLOOKUP(V5,'Exported Data'!$A:$A,'Exported Data'!$B:$B)} -> 10 | AF5: FALSE | AG5: Epheria
A6: T1 | C6: 3 | D6: 100 | E6: [Level 1] Roa Flower Seed Pouch | F6: =E6 -> [Level 1] Roa Flower Seed Pouch | G6: {=XLOOKUP(F6,'Exported Data'!A:A,'Exported Data'!B:B)} -> 2 | I6: ='Exported Data'!A20 -> [Level 2] Supreme Oyster Box | J6: =I6 -> [Level 2] Supreme Oyster Box | K6: {=XLOOKUP(J6,'Exported Data'!A:A,'Exported Data'!B:B)} -> 65 | M6: [Level 3] Rare Herb Pile | N6: =M6 -> [Level 3] Rare Herb Pile | O6: {=XLOOKUP(N6,'Exported Data'!$A:$A,'Exported Data'!$B:$B)} -> 21 | Q6: [Level 4] Old Chest with Gold Coins | R6: =Q6 -> [Level 4] Old Chest with Gold Coins | S6: {=XLOOKUP(R6,'Exported Data'!$A:$A,'Exported Data'!$B:$B)} -> 38 | U6: [Level 5] Stuffed White Caterpillar | V6: =U6 -> [Level 5] Stuffed White Caterpillar | W6: {=XLOOKUP(V6,'Exported Data'!$A:$A,'Exported Data'!$B:$B)} -> 0 | AF6: FALSE | AG6: Edania
A7: T2 | C7: 3 | D7: 400 | E7: [Level 1] Golden Sand | F7: =E7 -> [Level 1] Golden Sand | G7: {=XLOOKUP(F7,'Exported Data'!A:A,'Exported Data'!B:B)} -> 21 | I7: ='Exported Data'!A21 -> [Level 2] Sea Survival Kit | J7: =I7 -> [Level 2] Sea Survival Kit | K7: {=XLOOKUP(J7,'Exported Data'!A:A,'Exported Data'!B:B)} -> 70 | M7: [Level 3] Skull Symbol Carpet | N7: =M7 -> [Level 3] Skull Symbol Carpet | O7: {=XLOOKUP(N7,'Exported Data'!$A:$A,'Exported Data'!$B:$B)} -> 75 | Q7: [Level 4] Seashell Deco | R7: =Q7 -> [Level 4] Seashell Deco | S7: {=XLOOKUP(R7,'Exported Data'!$A:$A,'Exported Data'!$B:$B)} -> 15 | U7: [Level 5] Faded Gold Dragon Figurine | V7: =U7 -> [Level 5] Faded Gold Dragon Figurine | W7: {=XLOOKUP(V7,'Exported Data'!$A:$A,'Exported Data'!$B:$B)} -> 0
A8: T3 | B8: 15 | C8: 2 | D8: 900 | E8: [Level 1] Cherry Tree Seed Pouch | F8: =E8 -> [Level 1] Cherry Tree Seed Pouch | G8: {=XLOOKUP(F8,'Exported Data'!A:A,'Exported Data'!B:B)} -> 1 | I8: ='Exported Data'!A22 -> [Level 2] Urchin Spine | J8: =I8 -> [Level 2] Urchin Spine | K8: {=XLOOKUP(J8,'Exported Data'!A:A,'Exported Data'!B:B)} -> 33 | M8: [Level 3] Weasel Leather Coat | N8: =M8 -> [Level 3] Weasel Leather Coat | O8: {=XLOOKUP(N8,'Exported Data'!$A:$A,'Exported Data'!$B:$B)} -> 52 | Q8: [Level 4] Boatman's Manual | R8: =Q8 -> [Level 4] Boatman's Manual | S8: {=XLOOKUP(R8,'Exported Data'!$A:$A,'Exported Data'!$B:$B)} -> 42 | U8: [Level 5] Supreme Gold Candlestick | V8: =U8 -> [Level 5] Supreme Gold Candlestick | W8: {=XLOOKUP(V8,'Exported Data'!$A:$A,'Exported Data'!$B:$B)} -> 1
A9: T4 | C9: 1 | D9: 1000 | E9: [Level 1] Ancient Urn Piece | F9: =E9 -> [Level 1] Ancient Urn Piece | G9: {=XLOOKUP(F9,'Exported Data'!A:A,'Exported Data'!B:B)} -> 10 | I9: ='Exported Data'!A23 -> [Level 2] Pirate Ship Mast | J9: =I9 -> [Level 2] Pirate Ship Mast | K9: {=XLOOKUP(J9,'Exported Data'!A:A,'Exported Data'!B:B)} -> 11 | M9: [Level 3] Gooey Monster Blood | N9: =M9 -> [Level 3] Gooey Monster Blood | O9: {=XLOOKUP(N9,'Exported Data'!$A:$A,'Exported Data'!$B:$B)} -> 33 | Q9: [Level 4] Green Salt Lump | R9: =Q9 -> [Level 4] Green Salt Lump | S9: {=XLOOKUP(R9,'Exported Data'!$A:$A,'Exported Data'!$B:$B)} -> 17 | U9: [Level 5] Statue's Tear | V9: =U9 -> [Level 5] Statue's Tear | W9: {=XLOOKUP(V9,'Exported Data'!$A:$A,'Exported Data'!$B:$B)} -> 6 | Z9: Hakoven
A10: T5 | C10: 1 | D10: 1000 | E10: [Level 1] Chewy Raw Gizzard | F10: =E10 -> [Level 1] Chewy Raw Gizzard | G10: {=XLOOKUP(F10,'Exported Data'!A:A,'Exported Data'!B:B)} -> 3 | I10: ='Exported Data'!A24 -> [Level 2] Balanced Stone Pagoda | J10: =I10 -> [Level 2] Balanced Stone Pagoda | K10: {=XLOOKUP(J10,'Exported Data'!A:A,'Exported Data'!B:B)} -> 58 | M10: [Level 3] Round Knife | N10: =M10 -> [Level 3] Round Knife | O10: {=XLOOKUP(N10,'Exported Data'!$A:$A,'Exported Data'!$B:$B)} -> 39 | Q10: [Level 4] Solidified Lava | R10: =Q10 -> [Level 4] Solidified Lava | S10: {=XLOOKUP(R10,'Exported Data'!$A:$A,'Exported Data'!$B:$B)} -> 20 | U10: [Level 5] Stuffed Morpho Butterfly | V10: =U10 -> [Level 5] Stuffed Morpho Butterfly | W10: {=XLOOKUP(V10,'Exported Data'!$A:$A,'Exported Data'!$B:$B)} -> 6
A11: T6 e T7 | C11: 1 | D11: 2000 | E11: [Level 1] Raft Toy | F11: =E11 -> [Level 1] Raft Toy | G11: {=XLOOKUP(F11,'Exported Data'!A:A,'Exported Data'!B:B)} -> 3 | I11: ='Exported Data'!A25 -> [Level 2] Cron Castle Gold Coin | J11: =I11 -> [Level 2] Cron Castle Gold Coin | K11: {=XLOOKUP(J11,'Exported Data'!A:A,'Exported Data'!B:B)} -> 79 | M11: [Level 3] Skull Decorated Teacup | N11: =M11 -> [Level 3] Skull Decorated Teacup | O11: {=XLOOKUP(N11,'Exported Data'!$A:$A,'Exported Data'!$B:$B)} -> 70 | Q11: [Level 4] Marine Knights' Spear | R11: =Q11 -> [Level 4] Marine Knights' Spear | S11: {=XLOOKUP(R11,'Exported Data'!$A:$A,'Exported Data'!$B:$B)} -> 28 | U11: [Level 5] Azure Quartz | V11: =U11 -> [Level 5] Azure Quartz | W11: {=XLOOKUP(V11,'Exported Data'!$A:$A,'Exported Data'!$B:$B)} -> 3 | AF11: FALSE | AG11: Iliya
E12: [Level 1] Stained Seagull Figurine | F12: =E12 -> [Level 1] Stained Seagull Figurine | G12: {=XLOOKUP(F12,'Exported Data'!A:A,'Exported Data'!B:B)} -> 13 | I12: ='Exported Data'!A26 -> [Level 2] Opulent Marble | J12: =I12 -> [Level 2] Opulent Marble | K12: {=XLOOKUP(J12,'Exported Data'!A:A,'Exported Data'!B:B)} -> 45 | M12: [Level 3] Stalactite Fragment | N12: =M12 -> [Level 3] Stalactite Fragment | O12: {=XLOOKUP(N12,'Exported Data'!$A:$A,'Exported Data'!$B:$B)} -> 69 | Q12: [Level 4] Amethyst Fragment | R12: =Q12 -> [Level 4] Amethyst Fragment | S12: {=XLOOKUP(R12,'Exported Data'!$A:$A,'Exported Data'!$B:$B)} -> 24 | U12: [Level 5] Luxury Patterned Fabric | V12: =U12 -> [Level 5] Luxury Patterned Fabric | W12: {=XLOOKUP(V12,'Exported Data'!$A:$A,'Exported Data'!$B:$B)} -> 12 | AF12: TRUE | AG12: Epheria
E13: [Level 1] Naval Ration | F13: =E13 -> [Level 1] Naval Ration | G13: {=XLOOKUP(F13,'Exported Data'!A:A,'Exported Data'!B:B)} -> 33 | I13: ='Exported Data'!A27 -> [Level 2] Narvo Sea Cucumber | J13: =I13 -> [Level 2] Narvo Sea Cucumber | K13: {=XLOOKUP(J13,'Exported Data'!A:A,'Exported Data'!B:B)} -> 20 | M13: [Level 3] Scout Binoculars | N13: =M13 -> [Level 3] Scout Binoculars | O13: {=XLOOKUP(N13,'Exported Data'!$A:$A,'Exported Data'!$B:$B)} -> 55 | Q13: [Level 4] Opulent Thread Spool | R13: =Q13 -> [Level 4] Opulent Thread Spool | S13: {=XLOOKUP(R13,'Exported Data'!$A:$A,'Exported Data'!$B:$B)} -> 21 | U13: [Level 5] Octagonal Box | V13: =U13 -> [Level 5] Octagonal Box | W13: {=XLOOKUP(V13,'Exported Data'!$A:$A,'Exported Data'!$B:$B)} -> 5 | AF13: FALSE | AG13: Edania
E14: [Level 1] Giant Fish Bone | F14: =E14 -> [Level 1] Giant Fish Bone | I14: ='Exported Data'!A28 -> [Level 2] Island Tree Coated Plywood | J14: =I14 -> [Level 2] Island Tree Coated Plywood | K14: {=XLOOKUP(J14,'Exported Data'!A:A,'Exported Data'!B:B)} -> 30 | M14: [Level 3] Pirates' Supply Box | N14: =M14 -> [Level 3] Pirates' Supply Box | O14: {=XLOOKUP(N14,'Exported Data'!$A:$A,'Exported Data'!$B:$B)} -> 44 | Q14: [Level 4] Stolen Pirate Dagger | R14: =Q14 -> [Level 4] Stolen Pirate Dagger | S14: {=XLOOKUP(R14,'Exported Data'!$A:$A,'Exported Data'!$B:$B)} -> 28 | U14: [Level 5] Mysterious Rock | V14: =U14 -> [Level 5] Mysterious Rock | W14: {=XLOOKUP(V14,'Exported Data'!$A:$A,'Exported Data'!$B:$B)} -> 4
E15: [Level 1] Dried Blue Rose | F15: =E15 -> [Level 1] Dried Blue Rose | I15: ='Exported Data'!A29 -> [Level 2] Conch Shell Ornament | J15: =I15 -> [Level 2] Conch Shell Ornament | K15: {=XLOOKUP(J15,'Exported Data'!A:A,'Exported Data'!B:B)} -> 30 | M15: [Level 3] Torn Pirate Treasure Map | N15: =M15 -> [Level 3] Torn Pirate Treasure Map | O15: {=XLOOKUP(N15,'Exported Data'!$A:$A,'Exported Data'!$B:$B)} -> 26 | Q15: [Level 4] Marine Knights' Helm | R15: =Q15 -> [Level 4] Marine Knights' Helm | S15: {=XLOOKUP(R15,'Exported Data'!$A:$A,'Exported Data'!$B:$B)} -> 27 | U15: [Level 5] Valencia Sand Shield | V15: =U15 -> [Level 5] Valencia Sand Shield | W15: {=XLOOKUP(V15,'Exported Data'!$A:$A,'Exported Data'!$B:$B)} -> #N/A | Z15: Terra do Amanhecer
A16: Peso Base | B16: Peso Max | F16: =E16 | I16: ='Exported Data'!A30 -> [Level 2] Pirate Gold Coin | J16: =I16 -> [Level 2] Pirate Gold Coin | K16: {=XLOOKUP(J16,'Exported Data'!A:A,'Exported Data'!B:B)} -> 52 | M16: [Level 3] Old Hourglass | N16: =M16 -> [Level 3] Old Hourglass | O16: {=XLOOKUP(N16,'Exported Data'!$A:$A,'Exported Data'!$B:$B)} -> 21 | R16: =Q16 | S16: {=XLOOKUP(R16,'Exported Data'!$A:$A,'Exported Data'!$B:$B)} -> #N/A | V16: =U16 | W16: {=XLOOKUP(V16,'Exported Data'!$A:$A,'Exported Data'!$B:$B)} -> #N/A
A17: 2711 | B17: 23550 | AF17: FALSE | AG17: Iliya
A18: Peso Out | B18: Peso In | D18: this Sheet is linked to the Storage Manager Tab - it will inform you if you are low on any particular goods | R18: T1 less than 2 = | V18: T4 less than 6 = | AF18: FALSE | AG18: Epheria
A19: =(B6*D6)+(B7*D7)+(B8*D8)+(B9*D9)+(B10*D10)+(B11*C11)+A17 -> 16211 | B19: =((B6*C6)*400)+((B7*C7)*900)+((B8*C8)*D9)+((B9*C9)*D10)+((B10*C10)*D11)+A17 -> 32711 | D19: the Warning triggers at an amount lower to the max exchanges possible for the next Tier | R19: T2 less than 4 = | V19: T5 less than 5 = | AF19: TRUE | AG19: Edania
D20: E.g.: at Tier 3 a warning will appear when below or at 6 Goods / at T1 it would be below or at 2 Goods | R20: T3 less than 6 =
G21: Show? | H21: T6? | K21: Show? | M21: T6? | O21: Show? | P21: T6? | S21: Show? | U21: T6? | W21: Show? | X21: T6?
G22: TRUE | H22: TRUE | K22: FALSE | L22: FALSE | M22: FALSE | O22: TRUE | P22: TRUE | Q22: FALSE | S22: TRUE | T22: FALSE | U22: FALSE | W22: TRUE | X22: TRUE
A23: Custo | G23: TRUE | H23: TRUE | K23: TRUE | L23: FALSE | M23: TRUE | O23: TRUE | P23: FALSE | Q23: FALSE | S23: TRUE | T23: FALSE | U23: FALSE | W23: TRUE | X23: FALSE
A24: 8704 | G24: TRUE | H24: TRUE | K24: TRUE | L24: FALSE | M24: FALSE | O24: FALSE | P24: FALSE | Q24: FALSE | S24: FALSE | T24: FALSE | U24: FALSE

Sheet Dashboard

Sheet Full Barter Stock
A1: Full Barter Stock
C2: Tier 1 | F2: [Level 2] Balanced Stone Pagoda | G2: Tier 2 | K2: Tier 6
B3: [Level 1] Unidentified Ancient Mural | C3: =B3 -> [Level 1] Unidentified Ancient Mural | D3: {=XLOOKUP(C3,'Exported Data'!$A:$A,'Exported Data'!$B:$B)} -> 12 | F3: [Level 2] Islanders' Lunchbox | G3: =F3 -> [Level 2] Islanders' Lunchbox | H3: {=XLOOKUP(G3,'Exported Data'!$A:$A,'Exported Data'!$B:$B)} -> 57 | J3: [Level 6] Miniature Arehaza Lighthouse | K3: =J3 -> [Level 6] Miniature Arehaza Lighthouse | L3: {=XLOOKUP(K3,'Exported Data'!$A:$A,'Exported Data'!$B:$B)} -> 0
B4: [Level 1] Pirates' Gunpowder | C4: =B4 -> [Level 1] Pirates' Gunpowder | D4: {=XLOOKUP(C4,'Exported Data'!$A:$A,'Exported Data'!$B:$B)} -> 11 | F4: [Level 2] Monster Tentacle | G4: =F4 -> [Level 2] Monster Tentacle | H4: {=XLOOKUP(G4,'Exported Data'!$A:$A,'Exported Data'!$B:$B)} -> 32 | J4: [Level 6] Golden Cactus Bouquet | K4: =J4 -> [Level 6] Golden Cactus Bouquet | L4: {=XLOOKUP(K4,'Exported Data'!$A:$A,'Exported Data'!$B:$B)} -> 0
B5: [Level 1] Fertile Soil | C5: =B5 -> [Level 1] Fertile Soil | D5: {=XLOOKUP(C5,'Exported Data'!$A:$A,'Exported Data'!$B:$B)} -> 1 | F5: [Level 2] Filtered Drinking Water | G5: =F5 -> [Level 2] Filtered Drinking Water | H5: {=XLOOKUP(G5,'Exported Data'!$A:$A,'Exported Data'!$B:$B)} -> 81 | J5: [Level 6] Forest Fairy Perfume | K5: =J5 -> [Level 6] Forest Fairy Perfume | L5: {=XLOOKUP(K5,'Exported Data'!$A:$A,'Exported Data'!$B:$B)} -> 0
B6: [Level 1] Roa Flower Seed Pouch | C6: =B6 -> [Level 1] Roa Flower Seed Pouch | D6: {=XLOOKUP(C6,'Exported Data'!$A:$A,'Exported Data'!$B:$B)} -> 2 | F6: [Level 2] Supreme Oyster Box | G6: =F6 -> [Level 2] Supreme Oyster Box | H6: {=XLOOKUP(G6,'Exported Data'!$A:$A,'Exported Data'!$B:$B)} -> 65 | J6: [Level 6] Kamasylvian Sculpture | K6: =J6 -> [Level 6] Kamasylvian Sculpture | L6: {=XLOOKUP(K6,'Exported Data'!$A:$A,'Exported Data'!$B:$B)} -> 0
B7: [Level 1] Golden Sand | C7: =B7 -> [Level 1] Golden Sand | D7: {=XLOOKUP(C7,'Exported Data'!$A:$A,'Exported Data'!$B:$B)} -> 21 | F7: [Level 2] Sea Survival Kit | G7: =F7 -> [Level 2] Sea Survival Kit | H7: {=XLOOKUP(G7,'Exported Data'!$A:$A,'Exported Data'!$B:$B)} -> 70 | J7: [Level 6] Moonlit Crystal Lamp | K7: =J7 -> [Level 6] Moonlit Crystal Lamp | L7: {=XLOOKUP(K7,'Exported Data'!$A:$A,'Exported Data'!$B:$B)} -> 0
B8: [Level 1] Cherry Tree Seed Pouch | C8: =B8 -> [Level 1] Cherry Tree Seed Pouch | D8: {=XLOOKUP(C8,'Exported Data'!$A:$A,'Exported Data'!$B:$B)} -> 1 | F8: [Level 2] Urchin Spine | G8: =F8 -> [Level 2] Urchin Spine | H8: {=XLOOKUP(G8,'Exported Data'!$A:$A,'Exported Data'!$B:$B)} -> 33 | J8: [Level 6] Mossy Silver Log Decoration | K8: =J8 -> [Level 6] Mossy Silver Log Decoration | L8: {=XLOOKUP(K8,'Exported Data'!$A:$A,'Exported Data'!$B:$B)} -> 0
B9: [Level 1] Ancient Urn Piece | C9: =B9 -> [Level 1] Ancient Urn Piece | D9: {=XLOOKUP(C9,'Exported Data'!$A:$A,'Exported Data'!$B:$B)} -> 10 | F9: [Level 2] Pirate Ship Mast | G9: =F9 -> [Level 2] Pirate Ship Mast | H9: {=XLOOKUP(G9,'Exported Data'!$A:$A,'Exported Data'!$B:$B)} -> 11 | J9: [Level 6] Black Rose Bouquet | K9: =J9 -> [Level 6] Black Rose Bouquet | L9: {=XLOOKUP(K9,'Exported Data'!$A:$A,'Exported Data'!$B:$B)} -> 0
B10: [Level 1] Chewy Raw Gizzard | C10: =B10 -> [Level 1] Chewy Raw Gizzard | D10: {=XLOOKUP(C10,'Exported Data'!$A:$A,'Exported Data'!$B:$B)} -> 3 | F10: [Level 2] Balanced Stone Pagoda | G10: =F10 -> [Level 2] Balanced Stone Pagoda | H10: {=XLOOKUP(G10,'Exported Data'!$A:$A,'Exported Data'!$B:$B)} -> 58 | J10: [Level 6] Moonlit Crystal Shard | K10: =J10 -> [Level 6] Moonlit Crystal Shard | L10: {=XLOOKUP(K10,'Exported Data'!$A:$A,'Exported Data'!$B:$B)} -> 0
B11: [Level 1] Raft Toy | C11: =B11 -> [Level 1] Raft Toy | D11: {=XLOOKUP(C11,'Exported Data'!$A:$A,'Exported Data'!$B:$B)} -> 3 | F11: [Level 2] Cron Castle Gold Coin | G11: =F11 -> [Level 2] Cron Castle Gold Coin | H11: {=XLOOKUP(G11,'Exported Data'!$A:$A,'Exported Data'!$B:$B)} -> 79 | J11: [Level 6] Sharp Safflower Blade Crate | K11: =J11 -> [Level 6] Sharp Safflower Blade Crate | L11: {=XLOOKUP(K11,'Exported Data'!$A:$A,'Exported Data'!$B:$B)} -> 0
B12: [Level 1] Stained Seagull Figurine | C12: =B12 -> [Level 1] Stained Seagull Figurine | D12: {=XLOOKUP(C12,'Exported Data'!$A:$A,'Exported Data'!$B:$B)} -> 13 | F12: [Level 2] Opulent Marble | G12: =F12 -> [Level 2] Opulent Marble | H12: {=XLOOKUP(G12,'Exported Data'!$A:$A,'Exported Data'!$B:$B)} -> 45 | J12: [Level 6] Moonshade Aged Wine | K12: =J12 -> [Level 6] Moonshade Aged Wine | L12: {=XLOOKUP(K12,'Exported Data'!$A:$A,'Exported Data'!$B:$B)} -> 0
B13: [Level 1] Naval Ration | C13: =B13 -> [Level 1] Naval Ration | D13: {=XLOOKUP(C13,'Exported Data'!$A:$A,'Exported Data'!$B:$B)} -> 33 | F13: [Level 2] Narvo Sea Cucumber | G13: =F13 -> [Level 2] Narvo Sea Cucumber | H13: {=XLOOKUP(G13,'Exported Data'!$A:$A,'Exported Data'!$B:$B)} -> 20 | J13: [Level 6] Shadow Ornament Mirror | K13: =J13 -> [Level 6] Shadow Ornament Mirror | L13: {=XLOOKUP(K13,'Exported Data'!$A:$A,'Exported Data'!$B:$B)} -> 0
B14: [Level 1] Giant Fish Bone | C14: =B14 -> [Level 1] Giant Fish Bone | D14: {=XLOOKUP(C14,'Exported Data'!$A:$A,'Exported Data'!$B:$B)} -> 23 | F14: [Level 2] Island Tree Coated Plywood | G14: =F14 -> [Level 2] Island Tree Coated Plywood | H14: {=XLOOKUP(G14,'Exported Data'!$A:$A,'Exported Data'!$B:$B)} -> 30 | J14: [Level 6] Bamboo Sap Crate | K14: =J14 -> [Level 6] Bamboo Sap Crate | L14: {=XLOOKUP(K14,'Exported Data'!$A:$A,'Exported Data'!$B:$B)} -> 0
B15: [Level 1] Dried Blue Rose | C15: =B15 -> [Level 1] Dried Blue Rose | D15: {=XLOOKUP(C15,'Exported Data'!$A:$A,'Exported Data'!$B:$B)} -> 22 | F15: [Level 2] Conch Shell Ornament | G15: =F15 -> [Level 2] Conch Shell Ornament | H15: {=XLOOKUP(G15,'Exported Data'!$A:$A,'Exported Data'!$B:$B)} -> 30 | J15: [Level 6] Nampo Persimmon Crate | K15: =J15 -> [Level 6] Nampo Persimmon Crate | L15: {=XLOOKUP(K15,'Exported Data'!$A:$A,'Exported Data'!$B:$B)} -> 5
J16: [Level 6] High-quality Ink-scented Box | K16: =J16 -> [Level 6] High-quality Ink-scented Box | L16: {=XLOOKUP(K16,'Exported Data'!$A:$A,'Exported Data'!$B:$B)} -> 0
J17: [Level 6] Hanji Country Wild Berry Crate | K17: =J17 -> [Level 6] Hanji Country Wild Berry Crate | L17: {=XLOOKUP(K17,'Exported Data'!$A:$A,'Exported Data'!$B:$B)} -> 0
C18: Tier 3 | G18: Tier 4 | J18: [Level 6] Top-Quality Blue Underglaze Porcelain | K18: =J18 -> [Level 6] Top-Quality Blue Underglaze Porcelain | L18: {=XLOOKUP(K18,'Exported Data'!$A:$A,'Exported Data'!$B:$B)} -> 0
B19: [Level 3] Ancient Orders | C19: =B19 -> [Level 3] Ancient Orders | D19: {=XLOOKUP(C19,'Exported Data'!$A:$A,'Exported Data'!$B:$B)} -> 28 | F19: [Level 4] Green Salt Lump | G19: =F19 -> [Level 4] Green Salt Lump | H19: {=XLOOKUP(G19,'Exported Data'!$A:$A,'Exported Data'!$B:$B)} -> 17 | J19: [Level 6] Top-Quality Gamtu Crate | K19: =J19 -> [Level 6] Top-Quality Gamtu Crate | L19: {=XLOOKUP(K19,'Exported Data'!$A:$A,'Exported Data'!$B:$B)} -> 4
B20: [Level 3] Blue Candle Bundle | C20: =B20 -> [Level 3] Blue Candle Bundle | D20: {=XLOOKUP(C20,'Exported Data'!$A:$A,'Exported Data'!$B:$B)} -> 34 | F20: [Level 4] Panacea | G20: =F20 -> [Level 4] Panacea | H20: {=XLOOKUP(G20,'Exported Data'!$A:$A,'Exported Data'!$B:$B)} -> 81 | J20: [Level 6] Brass Bowl Crate | K20: =J20 -> [Level 6] Brass Bowl Crate | L20: {=XLOOKUP(K20,'Exported Data'!$A:$A,'Exported Data'!$B:$B)} -> 0
B21: [Level 3] Lopters Fishnet | C21: =B21 -> [Level 3] Lopters Fishnet | D21: {=XLOOKUP(C21,'Exported Data'!$A:$A,'Exported Data'!$B:$B)} -> 72 | F21: [Level 4] Marine Knights' Spear | G21: =F21 -> [Level 4] Marine Knights' Spear | H21: {=XLOOKUP(G21,'Exported Data'!$A:$A,'Exported Data'!$B:$B)} -> 28 | J21: [Level 6] Valencia Sand Shield | K21: =J21 -> [Level 6] Valencia Sand Shield | L21: {=XLOOKUP(K21,'Exported Data'!$A:$A,'Exported Data'!$B:$B)} -> 0
B22: [Level 3] Scout Binoculars | C22: =B22 -> [Level 3] Scout Binoculars | D22: {=XLOOKUP(C22,'Exported Data'!$A:$A,'Exported Data'!$B:$B)} -> 55 | F22: [Level 4] Marine Knights' Helm | G22: =F22 -> [Level 4] Marine Knights' Helm | H22: {=XLOOKUP(G22,'Exported Data'!$A:$A,'Exported Data'!$B:$B)} -> 27 | J22: [Level 6] Valencian Desert Fine Sword | K22: =J22 -> [Level 6] Valencian Desert Fine Sword | L22: {=XLOOKUP(K22,'Exported Data'!$A:$A,'Exported Data'!$B:$B)} -> 0
B23: [Level 3] Torn Pirate Treasure Map | C23: =B23 -> [Level 3] Torn Pirate Treasure Map | D23: {=XLOOKUP(C23,'Exported Data'!$A:$A,'Exported Data'!$B:$B)} -> 26 | F23: [Level 4] Boatman's Manual | G23: =F23 -> [Level 4] Boatman's Manual | H23: {=XLOOKUP(G23,'Exported Data'!$A:$A,'Exported Data'!$B:$B)} -> 42 | J23: [Level 6] Fancy Camel Hide | K23: =J23 -> [Level 6] Fancy Camel Hide | L23: {=XLOOKUP(K23,'Exported Data'!$A:$A,'Exported Data'!$B:$B)} -> 0
B24: [Level 3] Skull Decorated Teacup | C24: =B24 -> [Level 3] Skull Decorated Teacup | D24: {=XLOOKUP(C24,'Exported Data'!$A:$A,'Exported Data'!$B:$B)} -> 70 | F24: [Level 4] Old Chest with Gold Coins | G24: =F24 -> [Level 4] Old Chest with Gold Coins | H24: {=XLOOKUP(G24,'Exported Data'!$A:$A,'Exported Data'!$B:$B)} -> 38 | J24: [Level 6] Golden Sand Ring | K24: =J24 -> [Level 6] Golden Sand Ring | L24: {=XLOOKUP(K24,'Exported Data'!$A:$A,'Exported Data'!$B:$B)} -> 0
B25: [Level 3] Pirates' Supply Box | C25: =B25 -> [Level 3] Pirates' Supply Box | D25: {=XLOOKUP(C25,'Exported Data'!$A:$A,'Exported Data'!$B:$B)} -> 44 | F25: [Level 4] Headless Dragon Figurine | G25: =F25 -> [Level 4] Headless Dragon Figurine | H25: {=XLOOKUP(G25,'Exported Data'!$A:$A,'Exported Data'!$B:$B)} -> 26 | J25: [Level 6] Top-Quality Coconut Syrup | K25: =J25 -> [Level 6] Top-Quality Coconut Syrup | L25: {=XLOOKUP(K25,'Exported Data'!$A:$A,'Exported Data'!$B:$B)} -> 0
B26: [Level 3] Rare Herb Pile | C26: =B26 -> [Level 3] Rare Herb Pile | D26: {=XLOOKUP(C26,'Exported Data'!$A:$A,'Exported Data'!$B:$B)} -> 21 | F26: [Level 4] Solidified Lava | G26: =F26 -> [Level 4] Solidified Lava | H26: {=XLOOKUP(G26,'Exported Data'!$A:$A,'Exported Data'!$B:$B)} -> 20 | J26: [Level 6] Traditional Arehazan Tea | K26: =J26 -> [Level 6] Traditional Arehazan Tea | L26: {=XLOOKUP(K26,'Exported Data'!$A:$A,'Exported Data'!$B:$B)} -> 0
B27: [Level 3] Round Knife | C27: =B27 -> [Level 3] Round Knife | D27: {=XLOOKUP(C27,'Exported Data'!$A:$A,'Exported Data'!$B:$B)} -> 39 | F27: [Level 4] Bronze Candlestick | G27: =F27 -> [Level 4] Bronze Candlestick | H27: {=XLOOKUP(G27,'Exported Data'!$A:$A,'Exported Data'!$B:$B)} -> 4
B28: [Level 3] Weasel Leather Coat | C28: =B28 -> [Level 3] Weasel Leather Coat | D28: {=XLOOKUP(C28,'Exported Data'!$A:$A,'Exported Data'!$B:$B)} -> 52 | F28: [Level 4] Stolen Pirate Dagger | G28: =F28 -> [Level 4] Stolen Pirate Dagger | H28: {=XLOOKUP(G28,'Exported Data'!$A:$A,'Exported Data'!$B:$B)} -> 28 | K28: Tier 7
B29: [Level 3] Gooey Monster Blood | C29: =B29 -> [Level 3] Gooey Monster Blood | D29: {=XLOOKUP(C29,'Exported Data'!$A:$A,'Exported Data'!$B:$B)} -> 33 | F29: [Level 4] Seashell Deco | G29: =F29 -> [Level 4] Seashell Deco | H29: {=XLOOKUP(G29,'Exported Data'!$A:$A,'Exported Data'!$B:$B)} -> 15 | J29: [Level 7] Artisan's Seashell Necklace | K29: =J29 -> [Level 7] Artisan's Seashell Necklace | L29: {=XLOOKUP(K29,'Exported Data'!$A:$A,'Exported Data'!$B:$B)} -> 0
B30: [Level 3] Stalactite Fragment | C30: =B30 -> [Level 3] Stalactite Fragment | D30: {=XLOOKUP(C30,'Exported Data'!$A:$A,'Exported Data'!$B:$B)} -> 69 | F30: [Level 4] Pirate's Key | G30: =F30 -> [Level 4] Pirate's Key | H30: {=XLOOKUP(G30,'Exported Data'!$A:$A,'Exported Data'!$B:$B)} -> 26 | J30: [Level 7] Balenosian Sailor's Telescope | K30: =J30 -> [Level 7] Balenosian Sailor's Telescope | L30: {=XLOOKUP(K30,'Exported Data'!$A:$A,'Exported Data'!$B:$B)} -> 0
B31: [Level 3] Old Hourglass | C31: =B31 -> [Level 3] Old Hourglass | D31: {=XLOOKUP(C31,'Exported Data'!$A:$A,'Exported Data'!$B:$B)} -> 21 | F31: [Level 4] Opulent Thread Spool | G31: =F31 -> [Level 4] Opulent Thread Spool | H31: {=XLOOKUP(G31,'Exported Data'!$A:$A,'Exported Data'!$B:$B)} -> 21 | J31: [Level 7] Balenos Whale Sculpture | K31: =J31 -> [Level 7] Balenos Whale Sculpture | L31: {=XLOOKUP(K31,'Exported Data'!$A:$A,'Exported Data'!$B:$B)} -> 0
B32: [Level 3] Skull Symbol Carpet | C32: =B32 -> [Level 3] Skull Symbol Carpet | D32: {=XLOOKUP(C32,'Exported Data'!$A:$A,'Exported Data'!$B:$B)} -> 75 | F32: [Level 4] Amethyst Fragment | G32: =F32 -> [Level 4] Amethyst Fragment | H32: {=XLOOKUP(G32,'Exported Data'!$A:$A,'Exported Data'!$B:$B)} -> 24 | J32: [Level 7] Balenos Salt Flower | K32: =J32 -> [Level 7] Balenos Salt Flower | L32: {=XLOOKUP(K32,'Exported Data'!$A:$A,'Exported Data'!$B:$B)} -> 4
J33: [Level 7] Balenos Starlight Salt | K33: =J33 -> [Level 7] Balenos Starlight Salt | L33: {=XLOOKUP(K33,'Exported Data'!$A:$A,'Exported Data'!$B:$B)} -> 0
C34: Tier 5 | J34: [Level 7] Balenos Relic Fragment | K34: =J34 -> [Level 7] Balenos Relic Fragment | L34: {=XLOOKUP(K34,'Exported Data'!$A:$A,'Exported Data'!$B:$B)} -> 5
B35: [Level 5] Statue's Tear | C35: =B35 -> [Level 5] Statue's Tear | D35: {=XLOOKUP(C35,'Exported Data'!$A:$A,'Exported Data'!$B:$B)} -> 6 | J35: [Level 7] Balenos Rainbow Coral | K35: =J35 -> [Level 7] Balenos Rainbow Coral | L35: {=XLOOKUP(K35,'Exported Data'!$A:$A,'Exported Data'!$B:$B)} -> 0
B36: [Level 5] Mysterious Rock | C36: =B36 -> [Level 5] Mysterious Rock | D36: {=XLOOKUP(C36,'Exported Data'!$A:$A,'Exported Data'!$B:$B)} -> 4 | J36: [Level 7] Rainbow Sea Crystal Piece | K36: =J36 -> [Level 7] Rainbow Sea Crystal Piece | L36: {=XLOOKUP(K36,'Exported Data'!$A:$A,'Exported Data'!$B:$B)} -> 0
B37: [Level 5] Portrait of the Ancient | C37: =B37 -> [Level 5] Portrait of the Ancient | D37: {=XLOOKUP(C37,'Exported Data'!$A:$A,'Exported Data'!$B:$B)} -> 3 | J37: [Level 7] Top-Quality Heidelian Wine | K37: =J37 -> [Level 7] Top-Quality Heidelian Wine | L37: {=XLOOKUP(K37,'Exported Data'!$A:$A,'Exported Data'!$B:$B)} -> 0
B38: [Level 5] 102 Year Old Golden Herb | C38: =B38 -> [Level 5] 102 Year Old Golden Herb | D38: {=XLOOKUP(C38,'Exported Data'!$A:$A,'Exported Data'!$B:$B)} -> 6 | J38: [Level 7] Golden Flour Sack | K38: =J38 -> [Level 7] Golden Flour Sack | L38: {=XLOOKUP(K38,'Exported Data'!$A:$A,'Exported Data'!$B:$B)} -> 5
B39: [Level 5] Stuffed Morpho Butterfly | C39: =B39 -> [Level 5] Stuffed Morpho Butterfly | D39: {=XLOOKUP(C39,'Exported Data'!$A:$A,'Exported Data'!$B:$B)} -> 6 | J39: [Level 7] Organic Honey Crate | K39: =J39 -> [Level 7] Organic Honey Crate | L39: {=XLOOKUP(K39,'Exported Data'!$A:$A,'Exported Data'!$B:$B)} -> 0
B40: [Level 5] Supreme Gold Candlestick | C40: =B40 -> [Level 5] Supreme Gold Candlestick | D40: {=XLOOKUP(C40,'Exported Data'!$A:$A,'Exported Data'!$B:$B)} -> 1 | J40: [Level 7] Traditional Balenos Decorative Anchor | K40: =J40 -> [Level 7] Traditional Balenos Decorative Anchor | L40: {=XLOOKUP(K40,'Exported Data'!$A:$A,'Exported Data'!$B:$B)} -> 0
...

Sheet Item List
A1: Icon | B1: Sea Trade Good
A2: =IMAGE("https://bdocodex.com/items/new_icon/03_etc/10_free_tradeitem/00800008.webp") -> #REF! | B2: [Level 1] Unidentified Ancient Mural
A3: =IMAGE("https://bdocodex.com/items/new_icon/03_etc/10_free_tradeitem/00800037.webp") -> #REF! | B3: [Level 1] Pirates' Gunpowder
A4: =IMAGE("https://bdocodex.com/items/new_icon/03_etc/10_free_tradeitem/00800036.webp") -> #REF! | B4: [Level 1] Fertile Soil
A5: =IMAGE("https://bdocodex.com/items/new_icon/03_etc/10_free_tradeitem/00800015.webp") -> #REF! | B5: [Level 1] Roa Flower Seed Pouch
A6: =IMAGE("https://bdocodex.com/items/new_icon/03_etc/10_free_tradeitem/00800010.webp") -> #REF! | B6: [Level 1] Golden Sand
A7: =IMAGE("https://bdocodex.com/items/new_icon/03_etc/10_free_tradeitem/00800033.webp") -> #REF! | B7: [Level 1] Cherry Tree Seed Pouch
A8: =IMAGE("https://bdocodex.com/items/new_icon/03_etc/10_free_tradeitem/00800007.webp") -> #REF! | B8: [Level 1] Ancient Urn Piece
A9: =IMAGE("https://bdocodex.com/items/new_icon/03_etc/10_free_tradeitem/00800006.webp") -> #REF! | B9: [Level 1] Chewy Raw Gizzard
A10: =IMAGE("https://bdocodex.com/items/new_icon/03_etc/10_free_tradeitem/00800051.webp") -> #REF! | B10: [Level 1] Raft Toy
A11: =IMAGE("https://bdocodex.com/items/new_icon/03_etc/10_free_tradeitem/00800022.webp") -> #REF! | B11: [Level 1] Stained Seagull Figurine
A12: =IMAGE("https://bdocodex.com/items/new_icon/03_etc/10_free_tradeitem/00800003.webp") -> #REF! | B12: [Level 1] Naval Ration
A13: =IMAGE("https://bdocodex.com/items/new_icon/03_etc/10_free_tradeitem/00800026.webp") -> #REF! | B13: [Level 1] Giant Fish Bone
A14: =IMAGE("https://bdocodex.com/items/new_icon/03_etc/10_free_tradeitem/00800001.webp") -> #REF! | B14: [Level 1] Dried Blue Rose
A15: =IMAGE("https://bdocodex.com/items/new_icon/03_etc/10_free_tradeitem/00800060.webp") -> #REF! | B15: [Level 2] Islanders' Lunchbox
A16: =IMAGE("https://bdocodex.com/items/new_icon/03_etc/10_free_tradeitem/00800035.webp") -> #REF! | B16: [Level 2] Monster Tentacle
A17: =IMAGE("https://bdocodex.com/items/new_icon/03_etc/10_free_tradeitem/00800031.webp") -> #REF! | B17: [Level 2] Filtered Drinking Water
A18: =IMAGE("https://bdocodex.com/items/new_icon/03_etc/10_free_tradeitem/00800021.webp") -> #REF! | B18: [Level 2] Supreme Oyster Box
A19: =IMAGE("https://bdocodex.com/items/new_icon/03_etc/10_free_tradeitem/00800059.webp") -> #REF! | B19: [Level 2] Sea Survival Kit
A20: =IMAGE("https://bdocodex.com/items/new_icon/03_etc/10_free_tradeitem/00800049.webp") -> #REF! | B20: [Level 2] Urchin Spine
A21: =IMAGE("https://bdocodex.com/items/new_icon/03_etc/10_free_tradeitem/00800017.webp") -> #REF! | B21: [Level 2] Pirate Ship Mast
A22: =IMAGE("https://bdocodex.com/items/new_icon/03_etc/07_productmaterial/00005806.webp") -> #REF! | B22: Rock Salt Ingot
A23: =IMAGE("https://bdocodex.com/items/new_icon/03_etc/10_free_tradeitem/00800024.webp") -> #REF! | B23: [Level 2] Balanced Stone Pagoda
A24: =IMAGE("https://bdocodex.com/items/new_icon/03_etc/10_free_tradeitem/00800029.webp") -> #REF! | B24: [Level 2] Cron Castle Gold Coin
A25: =IMAGE("https://bdocodex.com/items/new_icon/03_etc/10_free_tradeitem/00800040.webp") -> #REF! | B25: [Level 2] Opulent Marble
A26: =IMAGE("https://bdocodex.com/items/new_icon/03_etc/10_free_tradeitem/00800023.webp") -> #REF! | B26: [Level 2] Narvo Sea Cucumber
A27: =IMAGE("https://bdocodex.com/items/new_icon/03_etc/07_productmaterial/00005805.webp") -> #REF! | B27: Island Tree Coated Plywood
A28: =IMAGE("https://bdocodex.com/items/new_icon/03_etc/10_free_tradeitem/00800020.webp") -> #REF! | B28: [Level 2] Conch Shell Ornament
A29: =IMAGE("https://bdocodex.com/items/new_icon/03_etc/10_free_tradeitem/00800027.webp") -> #REF! | B29: [Level 2] Pirate Gold Coin
A30: =IMAGE("https://bdocodex.com/items/new_icon/03_etc/10_free_tradeitem/00800042.webp") -> #REF! | B30: [Level 2] Big Stone Slab
A31: =IMAGE("https://bdocodex.com/items/new_icon/03_etc/10_free_tradeitem/00800054.webp") -> #REF! | B31: [Level 3] Ancient Orders
A32: =IMAGE("https://bdocodex.com/items/new_icon/03_etc/10_free_tradeitem/00800045.webp") -> #REF! | B32: [Level 3] Lopters Fishnet
A33: =IMAGE("https://bdocodex.com/items/new_icon/03_etc/10_free_tradeitem/00800032.webp") -> #REF! | B33: [Level 3] Scout Binoculars
A34: =IMAGE("https://bdocodex.com/items/new_icon/03_etc/10_free_tradeitem/00800052.webp") -> #REF! | B34: [Level 3] Torn Pirate Treasure Map
A35: =IMAGE("https://bdocodex.com/items/new_icon/03_etc/10_free_tradeitem/00800034.webp") -> #REF! | B35: [Level 3] Skull Decorated Teacup
A36: =IMAGE("https://bdocodex.com/items/new_icon/03_etc/10_free_tradeitem/00800053.webp") -> #REF! | B36: [Level 3] Pirates' Supply Box
A37: =IMAGE("https://bdocodex.com/items/new_icon/03_etc/10_free_tradeitem/00800002.webp") -> #REF! | B37: [Level 3] Rare Herb Pile
A38: =IMAGE("https://bdocodex.com/items/new_icon/03_etc/10_free_tradeitem/00800050.webp") -> #REF! | B38: [Level 3] Round Knife
A39: =IMAGE("https://bdocodex.com/items/new_icon/03_etc/10_free_tradeitem/00800070.webp") -> #REF! | B39: [Level 3] Weasel Leather Coat
A40: =IMAGE("https://bdocodex.com/items/new_icon/03_etc/10_free_tradeitem/00800048.webp") -> #REF! | B40: [Level 3] Gooey Monster Blood
...

Sheet Barter Item List Reference
A1: Icon | B1: Sea Trade Good | C1: Icon | D1: Sea Trade Good | E1: Icon | F1: Sea Trade Good | G1: Icon | H1: Sea Trade Good | I1: Icon | J1: Sea Trade Good | K1: Icon | L1: Sea Trade Good
A2: =IMAGE("https://bdocodex.com/items/new_icon/03_etc/10_free_tradeitem/00800060.webp") -> #REF! | B2: [Level 2] Islanders' Lunchbox | C2: =IMAGE("https://bdocodex.com/items/new_icon/03_etc/10_free_tradeitem/00800042.webp") -> #REF! | D2: [Level 2] Big Stone Slab | E2: =IMAGE("https://bdocodex.com/items/new_icon/03_etc/10_free_tradeitem/00800054.webp") -> #REF! | F2: [Level 3] Ancient Orders | G2: =IMAGE("https://bdocodex.com/items/new_icon/03_etc/10_free_tradeitem/00800061.webp") -> #REF! | H2: [Level 4] Green Salt Lump | I2: =IMAGE("https://bdocodex.com/items/new_icon/03_etc/10_free_tradeitem/00800046.webp") -> #REF! | J2: [Level 5] Statue's Tear | K2: =IMAGE("https://bdocodex.com/items/new_icon/03_etc/10_free_tradeitem/00800008.webp") -> #REF! | L2: [Level 1] Unidentified Ancient Mural
A3: =IMAGE("https://bdocodex.com/items/new_icon/03_etc/10_free_tradeitem/00800035.webp") -> #REF! | B3: [Level 2] Monster Tentacle | C3: =IMAGE("https://bdocodex.com/items/new_icon/03_etc/10_free_tradeitem/00800054.webp") -> #REF! | D3: [Level 3] Ancient Orders | E3: =IMAGE("https://bdocodex.com/items/new_icon/03_etc/10_free_tradeitem/00800056.webp") -> #REF! | F3: [Level 3] Blue Candle Bundle | G3: =IMAGE("https://bdocodex.com/items/new_icon/03_etc/10_free_tradeitem/00800025.webp") -> #REF! | H3: [Level 4] Panacea | I3: =IMAGE("https://bdocodex.com/items/new_icon/03_etc/10_free_tradeitem/00800009.webp") -> #REF! | J3: [Level 5] Mysterious Rock | K3: =IMAGE("https://bdocodex.com/items/new_icon/03_etc/10_free_tradeitem/00800037.webp") -> #REF! | L3: [Level 1] Pirates' Gunpowder
A4: =IMAGE("https://bdocodex.com/items/new_icon/03_etc/10_free_tradeitem/00800031.webp") -> #REF! | B4: [Level 2] Filtered Drinking Water | C4: =IMAGE("https://bdocodex.com/items/new_icon/03_etc/10_free_tradeitem/00800045.webp") -> #REF! | D4: [Level 3] Lopters Fishnet | E4: =IMAGE("https://bdocodex.com/items/new_icon/03_etc/10_free_tradeitem/00800032.webp") -> #REF! | F4: [Level 3] Scout Binoculars | G4: =IMAGE("https://bdocodex.com/items/new_icon/03_etc/10_free_tradeitem/00800065.webp") -> #REF! | H4: [Level 4] Marine Knights' Spear | I4: =IMAGE("https://bdocodex.com/items/new_icon/03_etc/10_free_tradeitem/00800067.webp") -> #REF! | J4: [Level 5] Portrait of the Ancient | K4: =IMAGE("https://bdocodex.com/items/new_icon/03_etc/10_free_tradeitem/00800036.webp") -> #REF! | L4: [Level 1] Fertile Soil
A5: =IMAGE("https://bdocodex.com/items/new_icon/03_etc/10_free_tradeitem/00800021.webp") -> #REF! | B5: [Level 2] Supreme Oyster Box | C5: =IMAGE("https://bdocodex.com/items/new_icon/03_etc/10_free_tradeitem/00800032.webp") -> #REF! | D5: [Level 3] Scout Binoculars | E5: =IMAGE("https://bdocodex.com/items/new_icon/03_etc/10_free_tradeitem/00800052.webp") -> #REF! | F5: [Level 3] Torn Pirate Treasure Map | G5: =IMAGE("https://bdocodex.com/items/new_icon/03_etc/10_free_tradeitem/00800043.webp") -> #REF! | H5: [Level 4] Marine Knights' Helm | I5: =IMAGE("https://bdocodex.com/items/new_icon/03_etc/10_free_tradeitem/00800011.webp") -> #REF! | J5: [Level 5] 102 Year Old Golden Herb | K5: =IMAGE("https://bdocodex.com/items/new_icon/03_etc/10_free_tradeitem/00800015.webp") -> #REF! | L5: [Level 1] Roa Flower Seed Pouch
A6: =IMAGE("https://bdocodex.com/items/new_icon/03_etc/10_free_tradeitem/00800059.webp") -> #REF! | B6: [Level 2] Sea Survival Kit | C6: =IMAGE("https://bdocodex.com/items/new_icon/03_etc/10_free_tradeitem/00800052.webp") -> #REF! | D6: [Level 3] Torn Pirate Treasure Map | E6: =IMAGE("https://bdocodex.com/items/new_icon/03_etc/10_free_tradeitem/00800004.webp") -> #REF! | F6: [Level 3] Old Hourglass | G6: =IMAGE("https://bdocodex.com/items/new_icon/03_etc/10_free_tradeitem/00800069.webp") -> #REF! | H6: [Level 4] Boatman's Manual | I6: =IMAGE("https://bdocodex.com/items/new_icon/03_etc/10_free_tradeitem/00800005.webp") -> #REF! | J6: [Level 5] Stuffed Morpho Butterfly | K6: =IMAGE("https://bdocodex.com/items/new_icon/03_etc/10_free_tradeitem/00800010.webp") -> #REF! | L6: [Level 1] Golden Sand
A7: =IMAGE("https://bdocodex.com/items/new_icon/03_etc/10_free_tradeitem/00800049.webp") -> #REF! | B7: [Level 2] Urchin Spine | C7: =IMAGE("https://bdocodex.com/items/new_icon/03_etc/10_free_tradeitem/00800034.webp") -> #REF! | D7: [Level 3] Skull Decorated Teacup | E7: =IMAGE("https://bdocodex.com/items/new_icon/03_etc/10_free_tradeitem/00800012.webp") -> #REF! | F7: [Level 4] Amethyst Fragment | G7: =IMAGE("https://bdocodex.com/items/new_icon/03_etc/10_free_tradeitem/00800018.webp") -> #REF! | H7: [Level 4] Old Chest with Gold Coins | I7: =IMAGE("https://bdocodex.com/items/new_icon/03_etc/10_free_tradeitem/00800028.webp") -> #REF! | J7: [Level 5] Supreme Gold Candlestick | K7: =IMAGE("https://bdocodex.com/items/new_icon/03_etc/10_free_tradeitem/00800033.webp") -> #REF! | L7: [Level 1] Cherry Tree Seed Pouch
A8: =IMAGE("https://bdocodex.com/items/new_icon/03_etc/10_free_tradeitem/00800017.webp") -> #REF! | B8: [Level 2] Pirate Ship Mast | C8: =IMAGE("https://bdocodex.com/items/new_icon/03_etc/10_free_tradeitem/00800053.webp") -> #REF! | D8: [Level 3] Pirates' Supply Box | E8: =IMAGE("https://bdocodex.com/items/new_icon/03_etc/10_free_tradeitem/00800043.webp") -> #REF! | F8: [Level 4] Marine Knights' Helm | G8: =IMAGE("https://bdocodex.com/items/new_icon/03_etc/10_free_tradeitem/00800041.webp") -> #REF! | H8: [Level 4] Headless Dragon Figurine | I8: =IMAGE("https://bdocodex.com/items/new_icon/03_etc/10_free_tradeitem/00800057.webp") -> #REF! | J8: [Level 5] Octagonal Box | K8: =IMAGE("https://bdocodex.com/items/new_icon/03_etc/10_free_tradeitem/00800007.webp") -> #REF! | L8: [Level 1] Ancient Urn Piece
A9: =IMAGE("https://bdocodex.com/items/new_icon/03_etc/07_productmaterial/00005806.webp") -> #REF! | B9: Rock Salt Ingot | C9: =IMAGE("https://bdocodex.com/items/new_icon/03_etc/10_free_tradeitem/00800002.webp") -> #REF! | D9: [Level 3] Rare Herb Pile | E9: =IMAGE("https://bdocodex.com/items/new_icon/03_etc/10_free_tradeitem/00800025.webp") -> #REF! | F9: [Level 4] Panacea | G9: =IMAGE("https://bdocodex.com/items/new_icon/03_etc/10_free_tradeitem/00800066.webp") -> #REF! | H9: [Level 4] Solidified Lava | I9: =IMAGE("https://bdocodex.com/items/new_icon/03_etc/10_free_tradeitem/00800039.webp") -> #REF! | J9: [Level 5] Golden Fish Scale | K9: =IMAGE("https://bdocodex.com/items/new_icon/03_etc/10_free_tradeitem/00800006.webp") -> #REF! | L9: [Level 1] Chewy Raw Gizzard
A10: =IMAGE("https://bdocodex.com/items/new_icon/03_etc/10_free_tradeitem/00800024.webp") -> #REF! | B10: [Level 2] Balanced Stone Pagoda | C10: =IMAGE("https://bdocodex.com/items/new_icon/03_etc/10_free_tradeitem/00800050.webp") -> #REF! | D10: [Level 3] Round Knife | E10: =IMAGE("https://bdocodex.com/items/new_icon/03_etc/10_free_tradeitem/00800066.webp") -> #REF! | F10: [Level 4] Solidified Lava | G10: =IMAGE("https://bdocodex.com/items/new_icon/03_etc/10_free_tradeitem/00800030.webp") -> #REF! | H10: [Level 4] Bronze Candlestick | I10: =IMAGE("https://bdocodex.com/items/new_icon/03_etc/10_free_tradeitem/00800044.webp") -> #REF! | J10: [Level 3] Skull Symbol Carpet | K10: =IMAGE("https://bdocodex.com/items/new_icon/03_etc/10_free_tradeitem/00800051.webp") -> #REF! | L10: [Level 1] Raft Toy
A11: =IMAGE("https://bdocodex.com/items/new_icon/03_etc/10_free_tradeitem/00800029.webp") -> #REF! | B11: [Level 2] Cron Castle Gold Coin | C11: =IMAGE("https://bdocodex.com/items/new_icon/03_etc/10_free_tradeitem/00800070.webp") -> #REF! | D11: [Level 3] Weasel Leather Coat | E11: =IMAGE("https://bdocodex.com/items/new_icon/03_etc/10_free_tradeitem/00800018.webp") -> #REF! | F11: [Level 4] Old Chest with Gold Coins | G11: =IMAGE("https://bdocodex.com/items/new_icon/03_etc/10_free_tradeitem/00800062.webp") -> #REF! | H11: [Level 4] Stolen Pirate Dagger | I11: =IMAGE("https://bdocodex.com/items/new_icon/03_etc/10_free_tradeitem/00800055.webp") -> #REF! | J11: [Level 5] Luxury Patterned Fabric | K11: =IMAGE("https://bdocodex.com/items/new_icon/03_etc/10_free_tradeitem/00800022.webp") -> #REF! | L11: [Level 1] Stained Seagull Figurine
A12: =IMAGE("https://bdocodex.com/items/new_icon/03_etc/10_free_tradeitem/00800040.webp") -> #REF! | B12: [Level 2] Opulent Marble | C12: =IMAGE("https://bdocodex.com/items/new_icon/03_etc/10_free_tradeitem/00800048.webp") -> #REF! | D12: [Level 3] Gooey Monster Blood | E12: =IMAGE("https://bdocodex.com/items/new_icon/03_etc/10_free_tradeitem/00800062.webp") -> #REF! | F12: [Level 4] Stolen Pirate Dagger | G12: =IMAGE("https://bdocodex.com/items/new_icon/03_etc/10_free_tradeitem/00800013.webp") -> #REF! | H12: [Level 4] Seashell Deco | I12: =IMAGE("https://bdocodex.com/items/new_icon/03_etc/10_free_tradeitem/00800213.webp") -> #REF! | J12: [Level 6] Valencia Sand Shield | K12: =IMAGE("https://bdocodex.com/items/new_icon/03_etc/10_free_tradeitem/00800003.webp") -> #REF! | L12: [Level 1] Naval Ration
A13: =IMAGE("https://bdocodex.com/items/new_icon/03_etc/10_free_tradeitem/00800023.webp") -> #REF! | B13: [Level 2] Narvo Sea Cucumber | C13: =IMAGE("https://bdocodex.com/items/new_icon/03_etc/10_free_tradeitem/00800047.webp") -> #REF! | D13: [Level 3] Stalactite Fragment | E13: =IMAGE("https://bdocodex.com/items/new_icon/03_etc/10_free_tradeitem/00800025.webp") -> #REF! | F13: [Level 4] Panacea | G13: =IMAGE("https://bdocodex.com/items/new_icon/03_etc/10_free_tradeitem/00800019.webp") -> #REF! | H13: [Level 5] Azure Quartz | I13: =IMAGE("https://bdocodex.com/items/new_icon/03_etc/10_free_tradeitem/00800214.webp") -> #REF! | J13: [Level 6] Valencian Desert Fine Sword | K13: =IMAGE("https://bdocodex.com/items/new_icon/03_etc/10_free_tradeitem/00800026.webp") -> #REF! | L13: [Level 1] Giant Fish Bone
A14: =IMAGE("https://bdocodex.com/items/new_icon/03_etc/07_productmaterial/00005805.webp") -> #REF! | B14: Island Tree Coated Plywood | C14: =IMAGE("https://bdocodex.com/items/new_icon/03_etc/10_free_tradeitem/00800004.webp") -> #REF! | D14: [Level 3] Old Hourglass | E14: =IMAGE("https://bdocodex.com/items/new_icon/03_etc/10_free_tradeitem/00800030.webp") -> #REF! | F14: [Level 4] Bronze Candlestick | G14: =IMAGE("https://bdocodex.com/items/new_icon/03_etc/10_free_tradeitem/00800068.webp") -> #REF! | H14: [Level 5] Elixir of Youth | I14: =IMAGE("https://bdocodex.com/items/new_icon/03_etc/10_free_tradeitem/00800215.webp") -> #REF! | J14: [Level 6] Fancy Camel Hide | K14: =IMAGE("https://bdocodex.com/items/new_icon/03_etc/10_free_tradeitem/00800001.webp") -> #REF! | L14: [Level 1] Dried Blue Rose
A15: =IMAGE("https://bdocodex.com/items/new_icon/03_etc/10_free_tradeitem/00800020.webp") -> #REF! | B15: [Level 2] Conch Shell Ornament | C15: =IMAGE("https://bdocodex.com/items/new_icon/03_etc/10_free_tradeitem/00800056.webp") -> #REF! | D15: [Level 3] Blue Candle Bundle | E15: =IMAGE("https://bdocodex.com/items/new_icon/03_etc/10_free_tradeitem/00800038.webp") -> #REF! | F15: [Level 4] Pirate's Key | G15: =IMAGE("https://bdocodex.com/items/new_icon/03_etc/10_free_tradeitem/00800014.webp") -> #REF! | H15: [Level 5] Faded Gold Dragon Figurine | I15: =IMAGE("https://bdocodex.com/items/new_icon/03_etc/10_free_tradeitem/00800216.webp") -> #REF! | J15: [Level 6] Golden Sand Ring
A16: =IMAGE("https://bdocodex.com/items/new_icon/03_etc/10_free_tradeitem/00800027.webp") -> #REF! | B16: [Level 2] Pirate Gold Coin | C16: =IMAGE("https://bdocodex.com/items/new_icon/03_etc/10_free_tradeitem/00800070.webp") -> #REF! | D16: [Level 3] Weasel Leather Coat | E16: =IMAGE("https://bdocodex.com/items/new_icon/03_etc/10_free_tradeitem/00800063.webp") -> #REF! | F16: [Level 4] Opulent Thread Spool | G16: =IMAGE("https://bdocodex.com/items/new_icon/03_etc/10_free_tradeitem/00800064.webp") -> #REF! | H16: [Level 5] Stuffed White Caterpillar | I16: =IMAGE("https://bdocodex.com/items/new_icon/03_etc/10_free_tradeitem/00800245.webp") -> #REF! | J16: [Level 6] Top-Quality Coconut Syrup
C17: =IMAGE("https://bdocodex.com/items/new_icon/03_etc/10_free_tradeitem/00800002.webp") -> #REF! | D17: [Level 3] Rare Herb Pile | E17: =IMAGE("https://bdocodex.com/items/new_icon/03_etc/10_free_tradeitem/00800012.webp") -> #REF! | F17: [Level 4] Amethyst Fragment | G17: =IMAGE("https://bdocodex.com/items/new_icon/03_etc/10_free_tradeitem/00800058.webp") -> #REF! | H17: [Level 5] 37 Year Old Herbal Wine | I17: =IMAGE("https://bdocodex.com/items/new_icon/03_etc/10_free_tradeitem/00800246.webp") -> #REF! | J17: [Level 6] Traditional Arehazan Tea
A18: Icon | B18: Sea Trade Good | C18: Icon | D18: Sea Trade Good | E18: Icon | F18: Sea Trade Good | G18: Icon | H18: Sea Trade Good | I18: Icon | J18: Sea Trade Good
A19: =IMAGE("https://bdocodex.com/items/new_icon/03_etc/10_free_tradeitem/00800247.webp") -> #REF! | B19: [Level 6] Miniature Arehaza Lighthouse | C19: =IMAGE("https://bdocodex.com/items/new_icon/03_etc/10_free_tradeitem/00800232.webp") -> #REF! | D19: [Level 6] Sharp Safflower Blade Crate | E19: =IMAGE("https://bdocodex.com/items/new_icon/03_etc/10_free_tradeitem/00800241.webp") -> #REF! | F19: [Level 7] Artisan's Seashell Necklace | G19: =IMAGE("https://bdocodex.com/items/new_icon/03_etc/10_free_tradeitem/00800223.webp") -> #REF! | H19: [Level 6] Moonshade Aged Wine | J19: [Level 7] Calpheonian Artisan's Pearl Necklaceac
A20: =IMAGE("https://bdocodex.com/items/new_icon/03_etc/10_free_tradeitem/00800248.webp") -> #REF! | B20: [Level 6] Golden Cactus Bouquet | C20: =IMAGE("https://bdocodex.com/items/new_icon/03_etc/10_free_tradeitem/00800201.webp") -> #REF! | D20: [Level 7] Top-Quality Heidelian Wine | E20: =IMAGE("https://bdocodex.com/items/new_icon/03_etc/10_free_tradeitem/00800242.webp") -> #REF! | F20: [Level 7] Balenosian Sailor's Telescope | G20: =IMAGE("https://bdocodex.com/items/new_icon/03_etc/10_free_tradeitem/00800224.webp") -> #REF! | H20: [Level 6] Shadow Ornament Mirror | I20: =IMAGE("https://bdocodex.com/items/new_icon/03_etc/10_free_tradeitem/00800209.webp") -> #REF! | J20: [Level 7] Sausan Military Supply
A21: =IMAGE("https://bdocodex.com/items/new_icon/03_etc/10_free_tradeitem/00800217.webp") -> #REF! | B21: [Level 6] Forest Fairy Perfume | C21: =IMAGE("https://bdocodex.com/items/new_icon/03_etc/10_free_tradeitem/00800202.webp") -> #REF! | D21: [Level 7] Golden Flour Sack | E21: =IMAGE("https://bdocodex.com/items/new_icon/03_etc/10_free_tradeitem/00800243.webp") -> #REF! | F21: [Level 7] Balenos Whale Sculpture | G21: =IMAGE("https://bdocodex.com/items/new_icon/03_etc/10_free_tradeitem/00800225.webp") -> #REF! | H21: [Level 6] Bamboo Sap Crate | I21: =IMAGE("https://bdocodex.com/items/new_icon/03_etc/10_free_tradeitem/00800210.webp") -> #REF! | J21: [Level 7] Stonetail Carrot Healthy Food Crate
A22: =IMAGE("https://bdocodex.com/items/new_icon/03_etc/10_free_tradeitem/00800218.webp") -> #REF! | B22: [Level 6] Kamasylvian Sculpture | C22: =IMAGE("https://bdocodex.com/items/new_icon/03_etc/10_free_tradeitem/00800203.webp") -> #REF! | D22: [Level 7] Organic Honey Crate | E22: =IMAGE("https://bdocodex.com/items/new_icon/03_etc/10_free_tradeitem/00800244.webp") -> #REF! | F22: [Level 7] Balenos Salt Flower | G22: =IMAGE("https://bdocodex.com/items/new_icon/03_etc/10_free_tradeitem/00800226.webp") -> #REF! | H22: [Level 6] Nampo Persimmon Crate | I22: =IMAGE("https://bdocodex.com/items/new_icon/03_etc/10_free_tradeitem/00800211.webp") -> #REF! | J22: [Level 7] Omar Lava Powder
A23: =IMAGE("https://bdocodex.com/items/new_icon/03_etc/10_free_tradeitem/00800219.webp") -> #REF! | B23: [Level 6] Moonlit Crystal Lamp | C23: =IMAGE("https://bdocodex.com/items/new_icon/03_etc/10_free_tradeitem/00800204.webp") -> #REF! | D23: [Level 7] Traditional Balenos Decorative Anchor | E23: =IMAGE("https://bdocodex.com/items/new_icon/03_etc/10_free_tradeitem/00800233.webp") -> #REF! | F23: [Level 7] Balenos Starlight Salt | G23: =IMAGE("https://bdocodex.com/items/new_icon/03_etc/10_free_tradeitem/00800227.webp") -> #REF! | H23: [Level 6] High-quality Ink-scented Box | J23: [Level 7] Tarif Magic Pot
A24: =IMAGE("https://bdocodex.com/items/new_icon/03_etc/10_free_tradeitem/00800220.webp") -> #REF! | B24: [Level 6] Mossy Silver Log Decoration | C24: =IMAGE("https://bdocodex.com/items/new_icon/03_etc/10_free_tradeitem/00800205.webp") -> #REF! | D24: [Level 7] Golden Eagle Brooch | E24: =IMAGE("https://bdocodex.com/items/new_icon/03_etc/10_free_tradeitem/00800234.webp") -> #REF! | F24: [Level 7] Balenos Relic Fragment | G24: =IMAGE("https://bdocodex.com/items/new_icon/03_etc/10_free_tradeitem/00800228.webp") -> #REF! | H24: [Level 6] Hanji Country Wild Berry Crate | I24: =IMAGE("https://bdocodex.com/items/new_icon/03_etc/10_free_tradeitem/00800237.webp") -> #REF! | J24: [Level 7] Rusalka's Thorny Bouquet
A25: =IMAGE("https://bdocodex.com/items/new_icon/03_etc/10_free_tradeitem/00800221.webp") -> #REF! | B25: [Level 6] Black Rose Bouquet | C25: =IMAGE("https://bdocodex.com/items/new_icon/03_etc/10_free_tradeitem/00800206.webp") -> #REF! | D25: [Level 7] Calpheon Knights' Combat Manual | E25: =IMAGE("https://bdocodex.com/items/new_icon/03_etc/10_free_tradeitem/00800235.webp") -> #REF! | F25: [Level 7] Balenos Rainbow Coral | G25: =IMAGE("https://bdocodex.com/items/new_icon/03_etc/10_free_tradeitem/00800229.webp") -> #REF! | H25: [Level 6] Top-Quality Blue Underglaze Porcelain Crate | I25: =IMAGE("https://bdocodex.com/items/new_icon/03_etc/10_free_tradeitem/00800238.webp") -> #REF! | J25: [Level 7] Sturdy Caphras Timber
A26: =IMAGE("https://bdocodex.com/items/new_icon/03_etc/10_free_tradeitem/00800222.webp") -> #REF! | B26: [Level 6] Moonlit Crystal Shard | C26: =IMAGE("https://bdocodex.com/items/new_icon/03_etc/10_free_tradeitem/00800207.webp") -> #REF! | D26: [Level 7] Calpheon Golden Candle Stand | E26: =IMAGE("https://bdocodex.com/items/new_icon/03_etc/10_free_tradeitem/00800236.webp") -> #REF! | F26: [Level 7] Rainbow Sea Crystal Piece | G26: =IMAGE("https://bdocodex.com/items/new_icon/03_etc/10_free_tradeitem/00800230.webp") -> #REF! | H26: [Level 6] Top-Quality Gamtu Crate | I26: =IMAGE("https://bdocodex.com/items/new_icon/03_etc/10_free_tradeitem/00800239.webp") -> #REF! | J26: [Level 7] Top-Quality Hakinza Perfume
G27: =IMAGE("https://bdocodex.com/items/new_icon/03_etc/10_free_tradeitem/00800231.webp") -> #REF! | H27: [Level 6] Brass Bowl Crate | I27: =IMAGE("https://bdocodex.com/items/new_icon/03_etc/10_free_tradeitem/00800240.webp") -> #REF! | J27: [Level 7] Throne of Edana Records

Sheet Storage Data
A1: Sea Trade Good | B1: Quantity
A2: [Level 2] Islanders' Lunchbox | B2: {=XLOOKUP(A2,'Exported Data'!A:A,'Exported Data'!B:B,0)} -> 57
A3: [Level 2] Monster Tentacle | B3: {=XLOOKUP(A3,'Exported Data'!A:A,'Exported Data'!B:B,0)} -> 32
A4: [Level 2] Filtered Drinking Water | B4: {=XLOOKUP(A4,'Exported Data'!A:A,'Exported Data'!B:B,0)} -> 81
A5: [Level 2] Supreme Oyster Box | B5: {=XLOOKUP(A5,'Exported Data'!A:A,'Exported Data'!B:B,0)} -> 65
A6: [Level 2] Sea Survival Kit | B6: {=XLOOKUP(A6,'Exported Data'!A:A,'Exported Data'!B:B,0)} -> 70
A7: [Level 2] Urchin Spine | B7: {=XLOOKUP(A7,'Exported Data'!A:A,'Exported Data'!B:B,0)} -> 33
A8: [Level 2] Pirate Ship Mast | B8: {=XLOOKUP(A8,'Exported Data'!A:A,'Exported Data'!B:B,0)} -> 11
A9: Rock Salt Ingot | B9: {=XLOOKUP(A9,'Exported Data'!A:A,'Exported Data'!B:B,0)} -> 0
A10: [Level 2] Balanced Stone Pagoda | B10: {=XLOOKUP(A10,'Exported Data'!A:A,'Exported Data'!B:B,0)} -> 58
A11: [Level 2] Cron Castle Gold Coin | B11: {=XLOOKUP(A11,'Exported Data'!A:A,'Exported Data'!B:B,0)} -> 79
A12: [Level 2] Opulent Marble | B12: {=XLOOKUP(A12,'Exported Data'!A:A,'Exported Data'!B:B,0)} -> 45
A13: [Level 2] Narvo Sea Cucumber | B13: {=XLOOKUP(A13,'Exported Data'!A:A,'Exported Data'!B:B,0)} -> 20
... A107: [Level 7] Rainbow Sea Crystal Piece | B107: {=XLOOKUP(A107,'Exported Data'!A:A,'Exported Data'!B:B,0)} -> 0

Sheet Exported Data
A1: Sea Trade Good | B1: Quantity
A2: Level 1 Items
A3: [Level 1] Unidentified Ancient Mural | B3: 12
A4: [Level 1] Pirates' Gunpowder | B4: 11
A5: [Level 1] Fertile Soil | B5: 1
A6: [Level 1] Roa Flower Seed Pouch | B6: 2
A7: [Level 1] Golden Sand | B7: 21
A8: [Level 1] Cherry Tree Seed Pouch | B8: 1
A9: [Level 1] Ancient Urn Piece | B9: 10
A10: [Level 1] Chewy Raw Gizzard | B10: 3
A11: [Level 1] Raft Toy | B11: 3
A12: [Level 1] Stained Seagull Figurine | B12: 13
A13: [Level 1] Naval Ration | B13: 33
A14: [Level 1] Giant Fish Bone | B14: 23
A15: [Level 1] Dried Blue Rose | B15: 22
A16: Level 2 Items
A17: [Level 2] Islanders' Lunchbox | B17: 57
A18: [Level 2] Monster Tentacle | B18: 32
A19: [Level 2] Filtered Drinking Water | B19: 81
A20: [Level 2] Supreme Oyster Box | B20: 65
A21: [Level 2] Sea Survival Kit | B21: 70
A22: [Level 2] Urchin Spine | B22: 33
A23: [Level 2] Pirate Ship Mast | B23: 11
A24: [Level 2] Balanced Stone Pagoda | B24: 58
A25: [Level 2] Cron Castle Gold Coin | B25: 79
A26: [Level 2] Opulent Marble | B26: 45
A27: [Level 2] Narvo Sea Cucumber | B27: 20
A28: [Level 2] Island Tree Coated Plywood | B28: 30
... A32: [Level 2] Big Stone Slab | B32: 30
A33: Level 3 Items
A34: [Level 3] Ancient Orders | B34: 28
A35: [Level 3] Blue Candle Bundle | B35: 34
A36: [Level 3] Lopters Fishnet | B36: 72
A37: [Level 3] Scout Binoculars | B37: 55
A38: [Level 3] Torn Pirate Treasure Map | B38: 26
A39: [Level 3] Skull Decorated Teacup | B39: 70
A40: [Level 3] Pirates' Supply Box | B40: 44
A41: [Level 3] Rare Herb Pile | B41: 21
A42: [Level 3] Round Knife | B42: 39
A43: [Level 3] Weasel Leather Coat | B43: 52
...
